Workbook

Sheet Dashboard
A1: Equity Price Targets — Dashboard
A2: Analyst consensus tracker · data via Yahoo Finance · auto-refreshed each trading day
A4: Tickers tracked | B4: =COUNTA('Price Targets'!A2:A1121)
A5: Tickers with live data | B5: =COUNT('Price Targets'!F2:F1121)
A6: Median upside to avg target | B6: =MEDIAN('Price Targets'!H2:H1121)
A7: Average dividend yield (payers) | B7: =AVERAGEIF('Price Targets'!O2:O1121,">0")
A8: Companies reporting in next 7 days | B8: =COUNTIFS('Price Targets'!Q2:Q1121,">="&TODAY(),'Price Targets'!Q2:Q1121,"<="&TODAY()+7)
A9: Largest upside to avg target | B9: =MAX('Price Targets'!H2:H1121)
A10: → ticker | B10: =INDEX('Price Targets'!A2:A1121,MATCH(MAX('Price Targets'!H2:H1121),'Price Targets'!H2:H1121,0))
A11: Smallest upside / largest downside | B11: =MIN('Price Targets'!H2:H1121)
A12: → ticker | B12: =INDEX('Price Targets'!A2:A1121,MATCH(MIN('Price Targets'!H2:H1121),'Price Targets'!H2:H1121,0))
A13: Combined market cap ($T) | B13: =SUM('Price Targets'!E2:E1121)/1000
A15: Data as of: 2026-10-28 01:32
A16: Legend: green = trading below analyst targets (upside), red = above (downside). Yellow earnings dates are within 7 days.

Sheet Price Targets
A1: Ticker | B1: Company | C1: Industry | D1: Country | E1: Market Cap ($B) | F1: Price ($) | G1: Avg Target ($) | H1: Upside to Avg (%) | I1: Min Target ($) | J1: Upside to Min (%) | K1: Max Target ($) | L1: Upside to Max (%) | M1: # Analysts | N1: Annual Div/Share ($) | O1: Div Yield (%) | P1: Ex-Div Date | Q1: Earnings Date | R1: TTM EPS ($) | S1: TTM P/E (x) | T1: Data As Of
A2: NVDA | B2: NVIDIA Corporation | C2: Semiconductors | D2: United States | E2: 5262.6 | F2: 217.94 | G2: 328.95346 | H2: =IF(AND(ISNUMBER(F2),ISNUMBER(G2),F2>0),G2/F2-1,"") | I2: 180 | J2: =IF(AND(ISNUMBER(F2),ISNUMBER(I2),F2>0),I2/F2-1,"") | K2: 515 | L2: =IF(AND(ISNUMBER(F2),ISNUMBER(K2),F2>0),K2/F2-1,"") | M2: 58 | N2: 1 | O2: =IF(AND(ISNUMBER(F2),ISNUMBER(N2),F2>0),N2/F2,"") | P2: 46275 | Q2: 46343 | R2: 7.91 | S2: =IF(AND(ISNUMBER(F2),ISNUMBER(R2),R2>0),F2/R2,"") | T2: 46323
A3: AAPL | B3: Apple Inc. | C3: Consumer Electronics | D3: United States | E3: 5065.64 | F3: 347.1 | G3: 330.0169 | H3: =IF(AND(ISNUMBER(F3),ISNUMBER(G3),F3>0),G3/F3-1,"") | I3: 240 | J3: =IF(AND(ISNUMBER(F3),ISNUMBER(I3),F3>0),I3/F3-1,"") | K3: 405 | L3: =IF(AND(ISNUMBER(F3),ISNUMBER(K3),F3>0),K3/F3-1,"") | M3: 39 | N3: 1.08 | O3: =IF(AND(ISNUMBER(F3),ISNUMBER(N3),F3>0),N3/F3,"") | P3: 46244 | Q3: 46328 | R3: 8.72 | S3: =IF(AND(ISNUMBER(F3),ISNUMBER(R3),R3>0),F3/R3,"") | T3: 46323
A4: MSFT | B4: Microsoft Corporation | C4: Software - Infrastructure | D4: United States | E4: 3945.42 | F4: 531.33 | G4: 605.1243 | H4: =IF(AND(ISNUMBER(F4),ISNUMBER(G4),F4>0),G4/F4-1,"") | I4: 440 | J4: =IF(AND(ISNUMBER(F4),ISNUMBER(I4),F4>0),I4/F4-1,"") | K4: 870 | L4: =IF(AND(ISNUMBER(F4),ISNUMBER(K4),F4>0),K4/F4-1,"") | M4: 53 | N4: 3.92 | O4: =IF(AND(ISNUMBER(F4),ISNUMBER(N4),F4>0),N4/F4,"") | P4: 46345 | Q4: 46323 | R4: 17.95 | S4: =IF(AND(ISNUMBER(F4),ISNUMBER(R4),R4>0),F4/R4,"") | T4: 46323
A5: GOOGL | B5: Alphabet Inc. | C5: Internet Content & Information | D5: United States | E5: 3920.67 | F5: 320.58 | G5: 429.12222 | H5: =IF(AND(ISNUMBER(F5),ISNUMBER(G5),F5>0),G5/F5-1,"") | I5: 340 | J5: =IF(AND(ISNUMBER(F5),ISNUMBER(I5),F5>0),I5/F5-1,"") | K5: 500 | L5: =IF(AND(ISNUMBER(F5),ISNUMBER(K5),F5>0),K5/F5-1,"") | M5: 54 | N5: 0.88 | O5: =IF(AND(ISNUMBER(F5),ISNUMBER(N5),F5>0),N5/F5,"") | P5: 46269 | Q5: 46323 | R5: 19.93 | S5: =IF(AND(ISNUMBER(F5),ISNUMBER(R5),R5>0),F5/R5,"") | T5: 46323
A6: AMZN | B6: Amazon.com, Inc. | C6: Internet Retail | D6: United States | E6: 2730.02 | F6: 253.1 | G6: 332.2369 | H6: =IF(AND(ISNUMBER(F6),ISNUMBER(G6),F6>0),G6/F6-1,"") | I6: 230 | J6: =IF(AND(ISNUMBER(F6),ISNUMBER(I6),F6>0),I6/F6-1,"") | K6: 405 | L6: =IF(AND(ISNUMBER(F6),ISNUMBER(K6),F6>0),K6/F6-1,"") | M6: 58 | O6: =IF(AND(ISNUMBER(F6),ISNUMBER(N6),F6>0),N6/F6,"") | Q6: 46324 | R6: 12.43 | S6: =IF(AND(ISNUMBER(F6),ISNUMBER(R6),R6>0),F6/R6,"") | T6: 46323
A7: TSM | B7: Taiwan Semiconductor Manufactur | C7: Semiconductors | D7: Taiwan | E7: 2265.81 | F7: 436.87 | G7: 584.39294 | H7: =IF(AND(ISNUMBER(F7),ISNUMBER(G7),F7>0),G7/F7-1,"") | I7: 440 | J7: =IF(AND(ISNUMBER(F7),ISNUMBER(I7),F7>0),I7/F7-1,"") | K7: 1000 | L7: =IF(AND(ISNUMBER(F7),ISNUMBER(K7),F7>0),K7/F7-1,"") | M7: 20 | N7: 3.77 | O7: =IF(AND(ISNUMBER(F7),ISNUMBER(N7),F7>0),N7/F7,"") | P7: 46366 | Q7: 46401 | R7: 15.43 | S7: =IF(AND(ISNUMBER(F7),ISNUMBER(R7),R7>0),F7/R7,"") | T7: 46323
A8: SPCX | B8: Space Exploration Technologies | C8: Aerospace & Defense | D8: United States | E8: 2017.87 | F8: 148.58 | G8: 256.58667 | H8: =IF(AND(ISNUMBER(F8),ISNUMBER(G8),F8>0),G8/F8-1,"") | I8: 70 | J8: =IF(AND(ISNUMBER(F8),ISNUMBER(I8),F8>0),I8/F8-1,"") | K8: 800 | L8: =IF(AND(ISNUMBER(F8),ISNUMBER(K8),F8>0),K8/F8-1,"") | M8: 36 | O8: =IF(AND(ISNUMBER(F8),ISNUMBER(N8),F8>0),N8/F8,"") | Q8: 46315 | R8: 0.23 | S8: =IF(AND(ISNUMBER(F8),ISNUMBER(R8),R8>0),F8/R8,"") | T8: 46323
A9: AVGO | B9: Broadcom Inc. | C9: Semiconductors | D9: United States | E9: 1634.16 | F9: 342.33 | G9: 530.14166 | H9: =IF(AND(ISNUMBER(F9),ISNUMBER(G9),F9>0),G9/F9-1,"") | I9: 215.88 | J9: =IF(AND(ISNUMBER(F9),ISNUMBER(I9),F9>0),I9/F9-1,"") | K9: 660 | L9: =IF(AND(ISNUMBER(F9),ISNUMBER(K9),F9>0),K9/F9-1,"") | M9: 48 | N9: 2.6 | O9: =IF(AND(ISNUMBER(F9),ISNUMBER(N9),F9>0),N9/F9,"") | P9: 46286 | Q9: 46365 | R9: 7.83 | S9: =IF(AND(ISNUMBER(F9),ISNUMBER(R9),R9>0),F9/R9,"") | T9: 46323
A10: TSLA | B10: Tesla, Inc. | C10: Auto Manufacturers | D10: United States | E10: 1610.58 | F10: 407.46 | G10: 410.68256 | H10: =IF(AND(ISNUMBER(F10),ISNUMBER(G10),F10>0),G10/F10-1,"") | I10: 128.11 | J10: =IF(AND(ISNUMBER(F10),ISNUMBER(I10),F10>0),I10/F10-1,"") | K10: 600 | L10: =IF(AND(ISNUMBER(F10),ISNUMBER(K10),F10>0),K10/F10-1,"") | M10: 39 | O10: =IF(AND(ISNUMBER(F10),ISNUMBER(N10),F10>0),N10/F10,"") | Q10: 46316 | R10: 0.91 | S10: =IF(AND(ISNUMBER(F10),ISNUMBER(R10),R10>0),F10/R10,"") | T10: 46323
A11: META | B11: Meta Platforms, Inc. | C11: Internet Content & Information | D11: United States | E11: 1585.72 | F11: 620.19 | G11: 846.79034 | H11: =IF(AND(ISNUMBER(F11),ISNUMBER(G11),F11>0),G11/F11-1,"") | I11: 629.06 | J11: =IF(AND(ISNUMBER(F11),ISNUMBER(I11),F11>0),I11/F11-1,"") | K11: 1050 | L11: =IF(AND(ISNUMBER(F11),ISNUMBER(K11),F11>0),K11/F11-1,"") | M11: 58 | N11: 2.1 | O11: =IF(AND(ISNUMBER(F11),ISNUMBER(N11),F11>0),N11/F11,"") | P11: 46286 | Q11: 46316 | R11: 29.31 | S11: =IF(AND(ISNUMBER(F11),ISNUMBER(R11),R11>0),F11/R11,"") | T11: 46323
A12: BRK.B | B12: Berkshire Hathaway Inc. New | C12: Insurance - Diversified | D12: United States | E12: 1162.38 | F12: 542.99 | G12: 555.6667 | H12: =IF(AND(ISNUMBER(F12),ISNUMBER(G12),F12>0),G12/F12-1,"") | I12: 510 | J12: =IF(AND(ISNUMBER(F12),ISNUMBER(I12),F12>0),I12/F12-1,"") | K12: 628 | L12: =IF(AND(ISNUMBER(F12),ISNUMBER(K12),F12>0),K12/F12-1,"") | M12: 3 | O12: =IF(AND(ISNUMBER(F12),ISNUMBER(N12),F12>0),N12/F12,"") | Q12: 46333 | R12: 39.76 | S12: =IF(AND(ISNUMBER(F12),ISNUMBER(R12),R12>0),F12/R12,"") | T12: 46323
A13: BRK.A | B13: Berkshire Hathaway Inc. | C13: Insurance - Diversified | D13: United States | E13: 1156.13 | F13: 810106 | G13: 808601.25 | H13: =IF(AND(ISNUMBER(F13),ISNUMBER(G13),F13>0),G13/F13-1,"") | I13: 735000 | J13: =IF(AND(ISNUMBER(F13),ISNUMBER(I13),F13>0),I13/F13-1,"") | K13: 942405 | L13: =IF(AND(ISNUMBER(F13),ISNUMBER(K13),F13>0),K13/F13-1,"") | M13: 4 | O13: =IF(AND(ISNUMBER(F13),ISNUMBER(N13),F13>0),N13/F13,"") | Q13: 46333 | R13: 59636.03 | S13: =IF(AND(ISNUMBER(F13),ISNUMBER(R13),R13>0),F13/R13,"") | T13: 46323
A14: LLY | B14: Eli Lilly and Company | C14: Drug Manufacturers - General | D14: United States | E14: 1143.13 | F14: 1281.91 | G14: 1333.7213 | H14: =IF(AND(ISNUMBER(F14),ISNUMBER(G14),F14>0),G14/F14-1,"") | I14: 930 | J14: =IF(AND(ISNUMBER(F14),ISNUMBER(I14),F14>0),I14/F14-1,"") | K14: 1600 | L14: =IF(AND(ISNUMBER(F14),ISNUMBER(K14),F14>0),K14/F14-1,"") | M14: 30 | N14: 6.92 | O14: =IF(AND(ISNUMBER(F14),ISNUMBER(N14),F14>0),N14/F14,"") | P14: 46339 | Q14: 46324 | R14: 29.79 | S14: =IF(AND(ISNUMBER(F14),ISNUMBER(R14),R14>0),F14/R14,"") | T14: 46323
A15: MU | B15: Micron Technology, Inc. | C15: Semiconductors | D15: United States | E15: 1050.82 | F15: 928.76 | G15: 1561.9111 | H15: =IF(AND(ISNUMBER(F15),ISNUMBER(G15),F15>0),G15/F15-1,"") | I15: 361 | J15: =IF(AND(ISNUMBER(F15),ISNUMBER(I15),F15>0),I15/F15-1,"") | K15: 3000 | L15: =IF(AND(ISNUMBER(F15),ISNUMBER(K15),F15>0),K15/F15-1,"") | M15: 45 | N15: 0.6 | O15: =IF(AND(ISNUMBER(F15),ISNUMBER(N15),F15>0),N15/F15,"") | P15: 46309 | Q15: 46379 | R15: 74.33 | S15: =IF(AND(ISNUMBER(F15),ISNUMBER(R15),R15>0),F15/R15,"") | T15: 46323
A16: SKHY | B16: SK hynix Inc. | C16: Semiconductors | D16: South Korea | E16: 1025.04 | F16: 145.36 | G16: 243.42857 | H16: =IF(AND(ISNUMBER(F16),ISNUMBER(G16),F16>0),G16/F16-1,"") | I16: 152 | J16: =IF(AND(ISNUMBER(F16),ISNUMBER(I16),F16>0),I16/F16-1,"") | K16: 320 | L16: =IF(AND(ISNUMBER(F16),ISNUMBER(K16),F16>0),K16/F16-1,"") | M16: 14 | N16: 0.11 | O16: =IF(AND(ISNUMBER(F16),ISNUMBER(N16),F16>0),N16/F16,"") | P16: 46265 | Q16: 46322 | R16: 15.68 | S16: =IF(AND(ISNUMBER(F16),ISNUMBER(R16),R16>0),F16/R16,"") | T16: 46323
A17: WMT | B17: Walmart Inc. | C17: Discount Stores | D17: United States | E17: 949.56 | F17: 119.32 | G17: 127.475 | H17: =IF(AND(ISNUMBER(F17),ISNUMBER(G17),F17>0),G17/F17-1,"") | I17: 81 | J17: =IF(AND(ISNUMBER(F17),ISNUMBER(I17),F17>0),I17/F17-1,"") | K17: 155 | L17: =IF(AND(ISNUMBER(F17),ISNUMBER(K17),F17>0),K17/F17-1,"") | M17: 40 | N17: 0.99 | O17: =IF(AND(ISNUMBER(F17),ISNUMBER(N17),F17>0),N17/F17,"") | P17: 46367 | Q17: 46345 | R17: 2.76 | S17: =IF(AND(ISNUMBER(F17),ISNUMBER(R17),R17>0),F17/R17,"") | T17: 46323
A18: AMD | B18: Advanced Micro Devices, Inc. | C18: Semiconductors | D18: United States | E18: 914.61 | F18: 560.26 | G18: 637.608 | H18: =IF(AND(ISNUMBER(F18),ISNUMBER(G18),F18>0),G18/F18-1,"") | I18: 365 | J18: =IF(AND(ISNUMBER(F18),ISNUMBER(I18),F18>0),I18/F18-1,"") | K18: 1250 | L18: =IF(AND(ISNUMBER(F18),ISNUMBER(K18),F18>0),K18/F18-1,"") | M18: 50 | O18: =IF(AND(ISNUMBER(F18),ISNUMBER(N18),F18>0),N18/F18,"") | Q18: 46329 | R18: 3.92 | S18: =IF(AND(ISNUMBER(F18),ISNUMBER(R18),R18>0),F18/R18,"") | T18: 46323
A19: JPM | B19: JP Morgan Chase & Co. | C19: Banks - Diversified | D19: United States | E19: 891.72 | F19: 335.79 | G19: 372.26086 | H19: =IF(AND(ISNUMBER(F19),ISNUMBER(G19),F19>0),G19/F19-1,"") | I19: 312 | J19: =IF(AND(ISNUMBER(F19),ISNUMBER(I19),F19>0),I19/F19-1,"") | K19: 425 | L19: =IF(AND(ISNUMBER(F19),ISNUMBER(K19),F19>0),K19/F19-1,"") | M19: 23 | N19: 6.6 | O19: =IF(AND(ISNUMBER(F19),ISNUMBER(N19),F19>0),N19/F19,"") | P19: 46301 | Q19: 46401 | R19: 23.84 | S19: =IF(AND(ISNUMBER(F19),ISNUMBER(R19),R19>0),F19/R19,"") | T19: 46323
A20: V | B20: Visa Inc. | C20: Credit Services | D20: United States | E20: 754.43 | F20: 401.86 | G20: 426.82108 | H20: =IF(AND(ISNUMBER(F20),ISNUMBER(G20),F20>0),G20/F20-1,"") | I20: 330 | J20: =IF(AND(ISNUMBER(F20),ISNUMBER(I20),F20>0),I20/F20-1,"") | K20: 480 | L20: =IF(AND(ISNUMBER(F20),ISNUMBER(K20),F20>0),K20/F20-1,"") | M20: 37 | N20: 2.68 | O20: =IF(AND(ISNUMBER(F20),ISNUMBER(N20),F20>0),N20/F20,"") | P20: 46245 | Q20: 46322 | R20: 11.75 | S20: =IF(AND(ISNUMBER(F20),ISNUMBER(R20),R20>0),F20/R20,"") | T20: 46323
A21: XOM | B21: ExxonMobil Holdings Corporation | C21: Oil & Gas Integrated | D21: United States | E21: 739.77 | F21: 179.91 | G21: 179.40909 | H21: =IF(AND(ISNUMBER(F21),ISNUMBER(G21),F21>0),G21/F21-1,"") | I21: 142 | J21: =IF(AND(ISNUMBER(F21),ISNUMBER(I21),F21>0),I21/F21-1,"") | K21: 206 | L21: =IF(AND(ISNUMBER(F21),ISNUMBER(K21),F21>0),K21/F21-1,"") | M21: 22 | N21: 4.12 | O21: =IF(AND(ISNUMBER(F21),ISNUMBER(N21),F21>0),N21/F21,"") | P21: 46251 | Q21: 46325 | R21: 7.77 | S21: =IF(AND(ISNUMBER(F21),ISNUMBER(R21),R21>0),F21/R21,"") | T21: 46323
A22: JNJ | B22: Johnson & Johnson | C22: Drug Manufacturers - General | D22: United States | E22: 646.92 | F22: 268.73 | G22: 279.4091 | H22: =IF(AND(ISNUMBER(F22),ISNUMBER(G22),F22>0),G22/F22-1,"") | I22: 190 | J22: =IF(AND(ISNUMBER(F22),ISNUMBER(I22),F22>0),I22/F22-1,"") | K22: 320 | L22: =IF(AND(ISNUMBER(F22),ISNUMBER(K22),F22>0),K22/F22-1,"") | M22: 22 | N22: 5.36 | O22: =IF(AND(ISNUMBER(F22),ISNUMBER(N22),F22>0),N22/F22,"") | P22: 46350 | Q22: 46308 | R22: 6.59 | S22: =IF(AND(ISNUMBER(F22),ISNUMBER(R22),R22>0),F22/R22,"") | T22: 46323
A23: ASML | B23: ASML Holding N.V. - New York Re | C23: Semiconductor Equipment & Materials | D23: Netherlands | E23: 630.38 | F23: 1635.57 | G23: 2134.3977 | H23: =IF(AND(ISNUMBER(F23),ISNUMBER(G23),F23>0),G23/F23-1,"") | I23: 860.9393 | J23: =IF(AND(ISNUMBER(F23),ISNUMBER(I23),F23>0),I23/F23-1,"") | K23: 2828.1382 | L23: =IF(AND(ISNUMBER(F23),ISNUMBER(K23),F23>0),K23/F23-1,"") | M23: 17 | N23: 9.08 | O23: =IF(AND(ISNUMBER(F23),ISNUMBER(N23),F23>0),N23/F23,"") | P23: 46322 | Q23: 46309 | R23: 40.64 | S23: =IF(AND(ISNUMBER(F23),ISNUMBER(R23),R23>0),F23/R23,"") | T23: 46323
A24: MA | B24: Mastercard Incorporated | C24: Credit Services | D24: United States | E24: 534.23 | F24: 609.85 | G24: 676.0381 | H24: =IF(AND(ISNUMBER(F24),ISNUMBER(G24),F24>0),G24/F24-1,"") | I24: 550 | J24: =IF(AND(ISNUMBER(F24),ISNUMBER(I24),F24>0),I24/F24-1,"") | K24: 765 | L24: =IF(AND(ISNUMBER(F24),ISNUMBER(K24),F24>0),K24/F24-1,"") | M24: 37 | N24: 3.48 | O24: =IF(AND(ISNUMBER(F24),ISNUMBER(N24),F24>0),N24/F24,"") | P24: 46304 | Q24: 46324 | R24: 18.18 | S24: =IF(AND(ISNUMBER(F24),ISNUMBER(R24),R24>0),F24/R24,"") | T24: 46323
A25: ABBV | B25: AbbVie Inc. | C25: Drug Manufacturers - General | D25: United States | E25: 506.08 | F25: 286.39 | G25: 283.18518 | H25: =IF(AND(ISNUMBER(F25),ISNUMBER(G25),F25>0),G25/F25-1,"") | I25: 200 | J25: =IF(AND(ISNUMBER(F25),ISNUMBER(I25),F25>0),I25/F25-1,"") | K25: 325 | L25: =IF(AND(ISNUMBER(F25),ISNUMBER(K25),F25>0),K25/F25-1,"") | M25: 27 | N25: 6.92 | O25: =IF(AND(ISNUMBER(F25),ISNUMBER(N25),F25>0),N25/F25,"") | P25: 46310 | Q25: 46325 | R25: 3.55 | S25: =IF(AND(ISNUMBER(F25),ISNUMBER(R25),R25>0),F25/R25,"") | T25: 46323
A26: INTC | B26: Intel Corporation | C26: Semiconductors | D26: United States | E26: 495.52 | F26: 93.74 | G26: 117.71429 | H26: =IF(AND(ISNUMBER(F26),ISNUMBER(G26),F26>0),G26/F26-1,"") | I26: 80 | J26: =IF(AND(ISNUMBER(F26),ISNUMBER(I26),F26>0),I26/F26-1,"") | K26: 200 | L26: =IF(AND(ISNUMBER(F26),ISNUMBER(K26),F26>0),K26/F26-1,"") | M26: 42 | O26: =IF(AND(ISNUMBER(F26),ISNUMBER(N26),F26>0),N26/F26,"") | Q26: 46324 | R26: -2.12 | S26: =IF(AND(ISNUMBER(F26),ISNUMBER(R26),R26>0),F26/R26,"") | T26: 46323
A27: PLTR | B27: Palantir Technologies Inc. | C27: Software - Infrastructure | D27: United States | E27: 477.56 | F27: 198.73 | G27: 208.96538 | H27: =IF(AND(ISNUMBER(F27),ISNUMBER(G27),F27>0),G27/F27-1,"") | I27: 80 | J27: =IF(AND(ISNUMBER(F27),ISNUMBER(I27),F27>0),I27/F27-1,"") | K27: 265 | L27: =IF(AND(ISNUMBER(F27),ISNUMBER(K27),F27>0),K27/F27-1,"") | M27: 26 | O27: =IF(AND(ISNUMBER(F27),ISNUMBER(N27),F27>0),N27/F27,"") | Q27: 46328 | R27: 1.17 | S27: =IF(AND(ISNUMBER(F27),ISNUMBER(R27),R27>0),F27/R27,"") | T27: 46323
A28: CVX | B28: Chevron Corporation | C28: Oil & Gas Integrated | D28: United States | E28: 447.7 | F28: 228.23 | G28: 232.5 | H28: =IF(AND(ISNUMBER(F28),ISNUMBER(G28),F28>0),G28/F28-1,"") | I28: 175 | J28: =IF(AND(ISNUMBER(F28),ISNUMBER(I28),F28>0),I28/F28-1,"") | K28: 272 | L28: =IF(AND(ISNUMBER(F28),ISNUMBER(K28),F28>0),K28/F28-1,"") | M28: 24 | N28: 7.12 | O28: =IF(AND(ISNUMBER(F28),ISNUMBER(N28),F28>0),N28/F28,"") | P28: 46253 | Q28: 46325 | R28: 10.39 | S28: =IF(AND(ISNUMBER(F28),ISNUMBER(R28),R28>0),F28/R28,"") | T28: 46323
A29: TCEHY | B29: Tencent Holding Ltd. | C29: Internet Content & Information | D29: China | E29: 445.37 | F29: 49.46 | G29: 88.25606 | H29: =IF(AND(ISNUMBER(F29),ISNUMBER(G29),F29>0),G29/F29-1,"") | I29: 80.06239 | J29: =IF(AND(ISNUMBER(F29),ISNUMBER(I29),F29>0),I29/F29-1,"") | K29: 99.67857 | L29: =IF(AND(ISNUMBER(F29),ISNUMBER(K29),F29>0),K29/F29-1,"") | M29: 4 | N29: 0.67 | O29: =IF(AND(ISNUMBER(F29),ISNUMBER(N29),F29>0),N29/F29,"") | P29: 46160 | Q29: 46344 | R29: 3.64 | S29: =IF(AND(ISNUMBER(F29),ISNUMBER(R29),R29>0),F29/R29,"") | T29: 46323
A30: COST | B30: Costco Wholesale Corporation | C30: Discount Stores | D30: United States | E30: 439.64 | F30: 992.13 | G30: 1067.5946 | H30: =IF(AND(ISNUMBER(F30),ISNUMBER(G30),F30>0),G30/F30-1,"") | I30: 770 | J30: =IF(AND(ISNUMBER(F30),ISNUMBER(I30),F30>0),I30/F30-1,"") | K30: 1315 | L30: =IF(AND(ISNUMBER(F30),ISNUMBER(K30),F30>0),K30/F30-1,"") | M30: 37 | N30: 5.88 | O30: =IF(AND(ISNUMBER(F30),ISNUMBER(N30),F30>0),N30/F30,"") | P30: 46325 | Q30: 46366 | R30: 20.76 | S30: =IF(AND(ISNUMBER(F30),ISNUMBER(R30),R30>0),F30/R30,"") | T30: 46323
A31: CSCO | B31: Cisco Systems, Inc. | C31: Communication Equipment | D31: United States | E31: 439.13 | F31: 111.38 | G31: 136.16 | H31: =IF(AND(ISNUMBER(F31),ISNUMBER(G31),F31>0),G31/F31-1,"") | I31: 110 | J31: =IF(AND(ISNUMBER(F31),ISNUMBER(I31),F31>0),I31/F31-1,"") | K31: 170 | L31: =IF(AND(ISNUMBER(F31),ISNUMBER(K31),F31>0),K31/F31-1,"") | M31: 25 | N31: 1.68 | O31: =IF(AND(ISNUMBER(F31),ISNUMBER(N31),F31>0),N31/F31,"") | P31: 46297 | Q31: 46338 | R31: 3.33 | S31: =IF(AND(ISNUMBER(F31),ISNUMBER(R31),R31>0),F31/R31,"") | T31: 46323
A32: ORCL | B32: Oracle Corporation | C32: Software - Infrastructure | D32: United States | E32: 395.7 | F32: 130.53 | G32: 235.8034 | H32: =IF(AND(ISNUMBER(F32),ISNUMBER(G32),F32>0),G32/F32-1,"") | I32: 110 | J32: =IF(AND(ISNUMBER(F32),ISNUMBER(I32),F32>0),I32/F32-1,"") | K32: 400 | L32: =IF(AND(ISNUMBER(F32),ISNUMBER(K32),F32>0),K32/F32-1,"") | M32: 41 | N32: 2 | O32: =IF(AND(ISNUMBER(F32),ISNUMBER(N32),F32>0),N32/F32,"") | P32: 46304 | Q32: 46370 | R32: 6.38 | S32: =IF(AND(ISNUMBER(F32),ISNUMBER(R32),R32>0),F32/R32,"") | T32: 46323
A33: KO | B33: Coca-Cola Company (The) | C33: Beverages - Non-Alcoholic | D33: United States | E33: 392.31 | F33: 91.18 | G33: 95.625 | H33: =IF(AND(ISNUMBER(F33),ISNUMBER(G33),F33>0),G33/F33-1,"") | I33: 80 | J33: =IF(AND(ISNUMBER(F33),ISNUMBER(I33),F33>0),I33/F33-1,"") | K33: 104 | L33: =IF(AND(ISNUMBER(F33),ISNUMBER(K33),F33>0),K33/F33-1,"") | M33: 24 | N33: 2.12 | O33: =IF(AND(ISNUMBER(F33),ISNUMBER(N33),F33>0),N33/F33,"") | P33: 46357 | Q33: 46322 | R33: 3.33 | S33: =IF(AND(ISNUMBER(F33),ISNUMBER(R33),R33>0),F33/R33,"") | T33: 46323
A34: RHHBY | B34: Roche Holding Ltd | C34: Drug Manufacturers - General | D34: Switzerland | E34: 384.42 | F34: 60.31 | G34: 60.01429 | H34: =IF(AND(ISNUMBER(F34),ISNUMBER(G34),F34>0),G34/F34-1,"") | I34: 52 | J34: =IF(AND(ISNUMBER(F34),ISNUMBER(I34),F34>0),I34/F34-1,"") | K34: 67.1 | L34: =IF(AND(ISNUMBER(F34),ISNUMBER(K34),F34>0),K34/F34-1,"") | M34: 7 | N34: 1.55 | O34: =IF(AND(ISNUMBER(F34),ISNUMBER(N34),F34>0),N34/F34,"") | P34: 46094 | Q34: 46051 | R34: 2.41 | S34: =IF(AND(ISNUMBER(F34),ISNUMBER(R34),R34>0),F34/R34,"") | T34: 46323
A35: PG | B35: Procter & Gamble Company (The) | C35: Household & Personal Products | D35: United States | E35: 369.06 | F35: 159.23 | G35: 173.30435 | H35: =IF(AND(ISNUMBER(F35),ISNUMBER(G35),F35>0),G35/F35-1,"") | I35: 143 | J35: =IF(AND(ISNUMBER(F35),ISNUMBER(I35),F35>0),I35/F35-1,"") | K35: 190 | L35: =IF(AND(ISNUMBER(F35),ISNUMBER(K35),F35>0),K35/F35-1,"") | M35: 23 | N35: 4.35 | O35: =IF(AND(ISNUMBER(F35),ISNUMBER(N35),F35>0),N35/F35,"") | P35: 46318 | Q35: 46408 | R35: 6.64 | S35: =IF(AND(ISNUMBER(F35),ISNUMBER(R35),R35>0),F35/R35,"") | T35: 46323
A36: UNH | B36: UnitedHealth Group Incorporated | C36: Healthcare Plans | D36: United States | E36: 368.36 | F36: 410.39 | G36: 476.64 | H36: =IF(AND(ISNUMBER(F36),ISNUMBER(G36),F36>0),G36/F36-1,"") | I36: 380 | J36: =IF(AND(ISNUMBER(F36),ISNUMBER(I36),F36>0),I36/F36-1,"") | K36: 531 | L36: =IF(AND(ISNUMBER(F36),ISNUMBER(K36),F36>0),K36/F36-1,"") | M36: 25 | N36: 9.28 | O36: =IF(AND(ISNUMBER(F36),ISNUMBER(N36),F36>0),N36/F36,"") | P36: 46279 | Q36: 46399 | R36: 15.55 | S36: =IF(AND(ISNUMBER(F36),ISNUMBER(R36),R36>0),F36/R36,"") | T36: 46323
A37: BAC | B37: Bank of America Corporation | C37: Banks - Diversified | D37: United States | E37: 350.84 | F37: 50.68 | G37: 62.95455 | H37: =IF(AND(ISNUMBER(F37),ISNUMBER(G37),F37>0),G37/F37-1,"") | I37: 56 | J37: =IF(AND(ISNUMBER(F37),ISNUMBER(I37),F37>0),I37/F37-1,"") | K37: 71 | L37: =IF(AND(ISNUMBER(F37),ISNUMBER(K37),F37>0),K37/F37-1,"") | M37: 22 | N37: 1.28 | O37: =IF(AND(ISNUMBER(F37),ISNUMBER(N37),F37>0),N37/F37,"") | P37: 46360 | Q37: 46402 | R37: 4.19 | S37: =IF(AND(ISNUMBER(F37),ISNUMBER(R37),R37>0),F37/R37,"") | T37: 46323
A38: MRK | B38: Merck & Company, Inc. | C38: Drug Manufacturers - General | D38: United States | E38: 349.89 | F38: 141.82 | G38: 159.76 | H38: =IF(AND(ISNUMBER(F38),ISNUMBER(G38),F38>0),G38/F38-1,"") | I38: 105 | J38: =IF(AND(ISNUMBER(F38),ISNUMBER(I38),F38>0),I38/F38-1,"") | K38: 186 | L38: =IF(AND(ISNUMBER(F38),ISNUMBER(K38),F38>0),K38/F38-1,"") | M38: 25 | N38: 3.4 | O38: =IF(AND(ISNUMBER(F38),ISNUMBER(N38),F38>0),N38/F38,"") | P38: 46280 | Q38: 46324 | R38: 1.24 | S38: =IF(AND(ISNUMBER(F38),ISNUMBER(R38),R38>0),F38/R38,"") | T38: 46323
A39: PANW | B39: Palo Alto Networks, Inc. | C39: Software - Infrastructure | D39: United States | E39: 328.59 | F39: 401.7 | G39: 398.52 | H39: =IF(AND(ISNUMBER(F39),ISNUMBER(G39),F39>0),G39/F39-1,"") | I39: 190 | J39: =IF(AND(ISNUMBER(F39),ISNUMBER(I39),F39>0),I39/F39-1,"") | K39: 525 | L39: =IF(AND(ISNUMBER(F39),ISNUMBER(K39),F39>0),K39/F39-1,"") | M39: 50 | O39: =IF(AND(ISNUMBER(F39),ISNUMBER(N39),F39>0),N39/F39,"") | Q39: 46345 | R39: 0.4 | S39: =IF(AND(ISNUMBER(F39),ISNUMBER(R39),R39>0),F39/R39,"") | T39: 46323
A40: CAT | B40: Caterpillar, Inc. | C40: Farm & Heavy Construction Machinery | D40: United States | E40: 327.89 | F40: 713.31 | G40: 926.9139 | H40: =IF(AND(ISNUMBER(F40),ISNUMBER(G40),F40>0),G40/F40-1,"") | I40: 575 | J40: =IF(AND(ISNUMBER(F40),ISNUMBER(I40),F40>0),I40/F40-1,"") | K40: 1150 | L40: =IF(AND(ISNUMBER(F40),ISNUMBER(K40),F40>0),K40/F40-1,"") | M40: 26 | N40: 6.52 | O40: =IF(AND(ISNUMBER(F40),ISNUMBER(N40),F40>0),N40/F40,"") | P40: 46321 | Q40: 46324 | R40: 23.23 | S40: =IF(AND(ISNUMBER(F40),ISNUMBER(R40),R40>0),F40/R40,"") | T40: 46323
...

Sheet Tickers
A1: Ticker | B1: Group | C1: HOW TO ADD A STOCK
A2: A | B2: S&P 100 / US | C2: This tab mirrors the ticker universe used by the automated refresh.
A3: AA | B3: S&P 100 / US | C3: To add or remove a stock: edit the tickers.txt file in the GitHub repo (one symbol per line),
A4: AAL | B4: S&P 100 / US | C4: or simply tell Claude (e.g. “add NFLX and COIN to my price targets sheet”).
A5: AAP | B5: S&P 100 / US | C5: The next scheduled refresh picks the change up automatically — no other edits needed.
A6: AAPL | B6: S&P 100 / US | C6: Note: use Yahoo-style symbols (BRK-B, not BRK.B) when editing tickers.txt.
A7: ABAT | B7: S&P 100 / US
A8: ABBV | B8: S&P 100 / US
A9: ABEV | B9: S&P 100 / US
A10: ABG | B10: S&P 100 / US
A11: ABNB | B11: S&P 100 / US
A12: ABT | B12: S&P 100 / US
A13: ACGL | B13: S&P 100 / US
A14: ACHC | B14: S&P 100 / US
A15: ACHR | B15: S&P 100 / US
A16: ACI | B16: S&P 100 / US
A17: ACIW | B17: S&P 100 / US
A18: ACN | B18: S&P 100 / US
... A1121: ZS | B1121: S&P 100 / US
